Workbook

Sheet Classification Matrix
A1: # | B1: Skill code | C1: Curriculum skill | D1: Cat. | E1: IXL category name | F1: Reasoning: what the student is actually doing | G1: Step 1 | H1: Step 2 | I1: Step 3 | J1: Pipeline | K1: Steps | L1: Composed? | M1: Type-checks? | N1: Changed in v2 re-pass
A2: 1 | B2: A.1 | C2: Factors | D2: A | E2: Numbers | F2: Break a number into its multiplicative parts | G2: Decompose | J2: Decompose | K2: =COUNTA(G2:I2) | L2: =IF(K2>1,"Composed","Atomic") | M2: Pass
A3: 2 | B3: A.2 | C3: Prime factorization | D3: A | E3: Numbers | F3: Break a number into irreducible components | G3: Decompose | J3: Decompose | K3: =COUNTA(G3:I3) | L3: =IF(K3>1,"Composed","Atomic") | M3: Pass
A4: 3 | B4: A.3 | C4: Greatest common factor | D4: A | E4: Numbers | F4: Decompose both numbers, then compare shared parts | G4: Decompose | H4: Compare | J4: Decompose -> Compare | K4: =COUNTA(G4:I4) | L4: =IF(K4>1,"Composed","Atomic") | M4: Pass
A5: 4 | B5: A.4 | C5: Least common multiple | D5: A | E5: Numbers | F5: Decompose, then rebuild the smallest shared whole | G5: Decompose | H5: Compose | J5: Decompose -> Compose | K5: =COUNTA(G5:I5) | L5: =IF(K5>1,"Composed","Atomic") | M5: Pass
A6: 5 | B6: A.5 | C6: GCF and LCM: word problems | D6: A | E6: Numbers | F6: Translate a situation, then decompose numbers | G6: Represent | H6: Decompose | I6: Compare | J6: Represent -> Decompose -> Compare | K6: =COUNTA(G6:I6) | L6: =IF(K6>1,"Composed","Atomic") | M6: Pass | N6: Was Represent+Decompose. Cap hid the Compare step.
A7: 6 | B7: A.6 | C7: Square roots | D7: A | E7: Numbers | F7: Rewrite a number as its inverse-power equivalent | G7: Transform | J7: Transform | K7: =COUNTA(G7:I7) | L7: =IF(K7>1,"Composed","Atomic") | M7: Pass
A8: 7 | B8: A.7 | C8: Cube roots | D8: A | E8: Numbers | F8: Rewrite a number as its inverse-power equivalent | G8: Transform | J8: Transform | K8: =COUNTA(G8:I8) | L8: =IF(K8>1,"Composed","Atomic") | M8: Pass
A9: 8 | B9: A.8 | C9: Classify rational and irrational numbers | D9: A | E9: Numbers | F9: Assign an object to a category by its properties | G9: Identify | J9: Identify | K9: =COUNTA(G9:I9) | L9: =IF(K9>1,"Composed","Atomic") | M9: Pass
A10: 9 | B10: A.9 | C10: Classify numbers | D10: A | E10: Numbers | F10: Assign an object to a category by its properties | G10: Identify | J10: Identify | K10: =COUNTA(G10:I10) | L10: =IF(K10>1,"Composed","Atomic") | M10: Pass
A11: 10 | B11: A.10 | C11: Compare and order rational numbers | D11: A | E11: Numbers | F11: Judge relative magnitude | G11: Compare | J11: Compare | K11: =COUNTA(G11:I11) | L11: =IF(K11>1,"Composed","Atomic") | M11: Pass
A12: 11 | B12: A.11 | C12: Absolute value and opposites | D12: A | E12: Numbers | F12: Rewrite a number under a distance/sign operation | G12: Transform | J12: Transform | K12: =COUNTA(G12:I12) | L12: =IF(K12>1,"Composed","Atomic") | M12: Pass | N12: Was Transform+Measure. Applying the operation is Transform.
A13: 12 | B13: A.12 | C13: Number lines | D13: A | E13: Numbers | F13: Place quantity onto a spatial representation | G13: Represent | J13: Represent | K13: =COUNTA(G13:I13) | L13: =IF(K13>1,"Composed","Atomic") | M13: Pass
A14: 13 | B14: A.13 | C14: Convert between decimals and fractions | D14: A | E14: Numbers | F14: Rewrite the same value in another notation | G14: Transform | J14: Transform | K14: =COUNTA(G14:I14) | L14: =IF(K14>1,"Composed","Atomic") | M14: Pass
A15: 14 | B15: B.1 | C15: Powers with integer bases | D15: B | E15: Exponents | F15: Rewrite a power in expanded/evaluated form | G15: Transform | J15: Transform | K15: =COUNTA(G15:I15) | L15: =IF(K15>1,"Composed","Atomic") | M15: Pass
A16: 15 | B16: B.2 | C16: Powers with decimal and fractional bases | D16: B | E16: Exponents | F16: Rewrite a power in expanded/evaluated form | G16: Transform | J16: Transform | K16: =COUNTA(G16:I16) | L16: =IF(K16>1,"Composed","Atomic") | M16: Pass
A17: 16 | B17: B.3 | C17: Negative exponents | D17: B | E17: Exponents | F17: Rewrite using an equivalent-form rule | G17: Transform | J17: Transform | K17: =COUNTA(G17:I17) | L17: =IF(K17>1,"Composed","Atomic") | M17: Pass
A18: 17 | B18: B.4 | C18: Multiplication with exponents | D18: B | E18: Exponents | F18: Rewrite using an equivalent-form rule | G18: Transform | J18: Transform | K18: =COUNTA(G18:I18) | L18: =IF(K18>1,"Composed","Atomic") | M18: Pass
A19: 18 | B19: B.5 | C19: Division with exponents | D19: B | E19: Exponents | F19: Rewrite using an equivalent-form rule | G19: Transform | J19: Transform | K19: =COUNTA(G19:I19) | L19: =IF(K19>1,"Composed","Atomic") | M19: Pass
A20: 19 | B20: B.6 | C20: Multiplication and division with exponents | D20: B | E20: Exponents | F20: Rewrite using an equivalent-form rule | G20: Transform | J20: Transform | K20: =COUNTA(G20:I20) | L20: =IF(K20>1,"Composed","Atomic") | M20: Pass
A21: 20 | B21: B.7 | C21: Power rule | D21: B | E21: Exponents | F21: Apply a general rewrite rule to any instance | G21: Transform | J21: Transform | K21: =COUNTA(G21:I21) | L21: =IF(K21>1,"Composed","Atomic") | M21: Pass | N21: Was Transform+Generalize. Applying the power rule is Transform executing its own rule, not generalizing.
A22: 21 | B22: B.8 | C22: Evaluate expressions using properties of exponents | D22: B | E22: Exponents | F22: Rewrite to canonical numeric form | G22: Transform | J22: Transform | K22: =COUNTA(G22:I22) | L22: =IF(K22>1,"Composed","Atomic") | M22: Pass
A23: 22 | B23: B.9 | C23: Identify equivalent expressions involving exponents | D23: B | E23: Exponents | F23: Rewrite candidates, then test sameness | G23: Transform | H23: Compare | J23: Transform -> Compare | K23: =COUNTA(G23:I23) | L23: =IF(K23>1,"Composed","Atomic") | M23: Pass
A24: 23 | B24: C.1 | C24: Convert between standard and scientific notation | D24: C | E24: Scientific notation | F24: Rewrite the same value in another notation | G24: Transform | J24: Transform | K24: =COUNTA(G24:I24) | L24: =IF(K24>1,"Composed","Atomic") | M24: Pass
A25: 24 | B25: C.2 | C25: Compare numbers written in scientific notation | D25: C | E25: Scientific notation | F25: Judge relative magnitude | G25: Compare | J25: Compare | K25: =COUNTA(G25:I25) | L25: =IF(K25>1,"Composed","Atomic") | M25: Pass | N25: Was Compare alone. Unchanged.
A26: 25 | B26: C.3 | C26: Multiply numbers written in scientific notation | D26: C | E26: Scientific notation | F26: Rewrite a product into canonical notation | G26: Transform | J26: Transform | K26: =COUNTA(G26:I26) | L26: =IF(K26>1,"Composed","Atomic") | M26: Pass
A27: 26 | B27: C.4 | C27: Divide numbers written in scientific notation | D27: C | E27: Scientific notation | F27: Rewrite a quotient into canonical notation | G27: Transform | J27: Transform | K27: =COUNTA(G27:I27) | L27: =IF(K27>1,"Composed","Atomic") | M27: Pass
A28: 27 | B28: D.1 | C28: Simplify radical expressions | D28: D | E28: Radical expressions | F28: Rewrite an equivalent representation | G28: Transform | J28: Transform | K28: =COUNTA(G28:I28) | L28: =IF(K28>1,"Composed","Atomic") | M28: Pass
A29: 28 | B29: D.2 | C29: Simplify radical expressions by rationalizing the denominator | D29: D | E29: Radical expressions | F29: Rewrite an equivalent representation | G29: Transform | J29: Transform | K29: =COUNTA(G29:I29) | L29: =IF(K29>1,"Composed","Atomic") | M29: Pass
A30: 29 | B30: D.3 | C30: Multiply radical expressions | D30: D | E30: Radical expressions | F30: Rewrite an equivalent representation | G30: Transform | J30: Transform | K30: =COUNTA(G30:I30) | L30: =IF(K30>1,"Composed","Atomic") | M30: Pass
A31: 30 | B31: D.4 | C31: Add and subtract radical expressions | D31: D | E31: Radical expressions | F31: Rewrite an equivalent representation | G31: Transform | J31: Transform | K31: =COUNTA(G31:I31) | L31: =IF(K31>1,"Composed","Atomic") | M31: Pass
A32: 31 | B32: D.5 | C32: Simplify radical expressions using the distributive property | D32: D | E32: Radical expressions | F32: Rewrite an equivalent representation | G32: Transform | J32: Transform | K32: =COUNTA(G32:I32) | L32: =IF(K32>1,"Composed","Atomic") | M32: Pass
A33: 32 | B33: D.6 | C33: Simplify radical expressions: mixed review | D33: D | E33: Radical expressions | F33: Rewrite an equivalent representation | G33: Transform | J33: Transform | K33: =COUNTA(G33:I33) | L33: =IF(K33>1,"Composed","Atomic") | M33: Pass
A34: 33 | B34: E.1 | C34: Evaluate rational exponents | D34: E | E34: Rational exponents | F34: Rewrite to canonical numeric form | G34: Transform | J34: Transform | K34: =COUNTA(G34:I34) | L34: =IF(K34>1,"Composed","Atomic") | M34: Pass
A35: 34 | B35: E.2 | C35: Multiplication with rational exponents | D35: E | E35: Rational exponents | F35: Rewrite using an equivalent-form rule | G35: Transform | J35: Transform | K35: =COUNTA(G35:I35) | L35: =IF(K35>1,"Composed","Atomic") | M35: Pass
A36: 35 | B36: E.3 | C36: Division with rational exponents | D36: E | E36: Rational exponents | F36: Rewrite using an equivalent-form rule | G36: Transform | J36: Transform | K36: =COUNTA(G36:I36) | L36: =IF(K36>1,"Composed","Atomic") | M36: Pass
A37: 36 | B37: E.4 | C37: Power rule with rational exponents | D37: E | E37: Rational exponents | F37: Apply a general rewrite rule to any instance | G37: Transform | J37: Transform | K37: =COUNTA(G37:I37) | L37: =IF(K37>1,"Composed","Atomic") | M37: Pass | N37: Was Transform+Generalize. Same as B.7.
A38: 37 | B38: E.5 | C38: Simplify expressions involving rational exponents I | D38: E | E38: Rational exponents | F38: Rewrite an equivalent representation | G38: Transform | J38: Transform | K38: =COUNTA(G38:I38) | L38: =IF(K38>1,"Composed","Atomic") | M38: Pass
A39: 38 | B39: E.6 | C39: Simplify expressions involving rational exponents II | D39: E | E39: Rational exponents | F39: Rewrite an equivalent representation | G39: Transform | J39: Transform | K39: =COUNTA(G39:I39) | L39: =IF(K39>1,"Composed","Atomic") | M39: Pass
A40: 39 | B40: F.1 | C40: Coordinate plane review | D40: F | E40: Coordinate plane | F40: Map between points and coordinate notation | G40: Represent | J40: Represent | K40: =COUNTA(G40:I40) | L40: =IF(K40>1,"Composed","Atomic") | M40: Pass
...

Sheet Primitive Vocabulary
A1: Deliverable 1 & 3 - Primitives as typed operations
A2: Each primitive is an operation with a signature and a rule. Nine are mechanical; one (Generalize) is not.
A4: Primitive | B4: Rule kind | C4: Does it have a definable rule? | D4: What its rule looks like | E4: Example rules / formulas it carries | F4: Accepts (input types) | G4: Returns (output type) | H4: Times used | I4: As final step | J4: Mid-pipeline
A5: Identify | B5: Classifier | C5: Yes | D5: A checklist of defining properties. Object in, category out. | E5: Vertical line test; quadrilateral property checklist; leading-coefficient sign | F5: Object, Parts, Relation, Rule, Value | G5: Category | H5: =COUNTIF('Classification Matrix'!$G$2:$I$307,$A5) | I5: 35 | J5: 0
A6: Represent | B6: Translator | C6: Yes | D6: A mapping between two notations. Same content, new form. | E6: Point plotting; slope-intercept to graph; SOH-CAH-TOA set-up; net unfolding | F6: Object, Parts, Relation, Rule, Value | G6: Object | H6: =COUNTIF('Classification Matrix'!$G$2:$I$307,$A6) | I6: 57 | J6: 26
A7: Transform | B7: Producer | C7: Yes | D7: An equivalence-preserving rewrite rule. | E7: Exponent laws; radical simplification; distributive property; unit conversion | F7: Object, Parts, Rule, Value | G7: Object | H7: =COUNTIF('Classification Matrix'!$G$2:$I$307,$A7) | I7: 64 | J7: 18
A8: Compare | B8: Producer | C8: Yes | D8: A relation-extraction rule. Two objects in, a relation out. | E8: Ordering on the number line; ratio of corresponding sides; scale factor | F8: Object, Parts, Value | G8: Relation | H8: =COUNTIF('Classification Matrix'!$G$2:$I$307,$A8) | I8: 17 | J8: 8
A9: Compose | B9: Producer | C9: Yes | D9: An assembly rule. Parts in, one whole out. | E9: Counting principle; sum of partial areas; composition of transformations | F9: Object, Parts, Value | G9: Object | H9: =COUNTIF('Classification Matrix'!$G$2:$I$307,$A9) | I9: 7 | J9: 6
A10: Decompose | B10: Producer | C10: Yes | D10: A splitting rule. One whole in, parts out. | E10: Prime factorization; factoring quadratics; net decomposition; long division | F10: Object | G10: Parts | H10: =COUNTIF('Classification Matrix'!$G$2:$I$307,$A10) | I10: 12 | J10: 11
A11: Constrain | B11: Producer | C11: Yes | D11: A solution procedure over stated conditions. | E11: Isolate the variable; quadratic formula; elimination; Pythagorean relation | F11: Object, Parts, Relation, Rule, Value | G11: Value | H11: =COUNTIF('Classification Matrix'!$G$2:$I$307,$A11) | I11: 47 | J11: 4
A12: Measure | B12: Producer | C12: Yes | D12: A quantification formula. Object in, magnitude out. | E12: A = 1/2bh; slope = rise/run; (n-2)x180; mean; P(E) = favourable/total | F12: Object, Parts, Relation, Value | G12: Value | H12: =COUNTIF('Classification Matrix'!$G$2:$I$307,$A12) | I12: 46 | J12: 17
A13: Generalize | B13: Inducer | C13: NO - inductive, not mechanical | D13: NO FORMULA EXISTS. Cases in, a new rule out. The one non-mechanical primitive. | E13: Line of best fit; writing the rule for a mapping; deriving f(x) from a table | F13: Cases, Object, Value | G13: Rule | H13: =COUNTIF('Classification Matrix'!$G$2:$I$307,$A13) | I13: 4 | J13: 3
A14: Verify | B14: Tester | C14: Yes | D14: A criterion returning true or false. Terminal - nothing consumes a Boolean. | E14: Substitution check; SSS/SAS criteria; triangle inequality; counterexample search | F14: Category, Object, Parts, Relation, Rule, Value | G14: Boolean | H14: =COUNTIF('Classification Matrix'!$G$2:$I$307,$A14) | I14: 17 | J14: 0
A17: Reading this sheet
A18: A primitive is an operation: it accepts certain input types and returns exactly one output type. The 'rule' is what the student is taught once and then reuses everywhere the primitive appears.
A19: Identify and Verify are highlighted because they NEVER appear mid-pipeline (0 occurrences in 306 skills). The type system predicts this: they return Category and Boolean, and nothing downstream consumes those. The prediction was not enforced during classification - it emerged from the data.
A20: Generalize is the only primitive with no definable rule. It appears in just 7 of 306 skills, which locates the non-mechanical part of Grade 10 mathematics precisely.

Sheet Pipeline Library
A1: The composition layer - every distinct program over the primitives
A2: 306 curriculum skills reduce to this many distinct pipelines. This is the compression the hypothesis predicts.
A4: Rank | B4: Pipeline | C4: Length | D4: Skills using it | E4: % of curriculum | F4: Cumulative % | G4: Example skill
A5: 1 | B5: Transform | C5: 1 | D5: 60 | E5: 0.19607843 | F5: 0.19607843 | G5: A.6 Square roots
A6: 2 | B6: Represent | C6: 1 | D6: 36 | E6: 0.11764706 | F6: 0.31372549 | G6: A.12 Number lines
A7: 3 | B7: Measure | C7: 1 | D7: 31 | E7: 0.10130719 | F7: 0.41503268 | G7: F.2 Midpoints
A8: 4 | B8: Constrain | C8: 1 | D8: 30 | E8: 0.098039216 | F8: 0.5130719 | G8: G.3 Solve one-step linear equations
A9: 5 | B9: Identify | C9: 1 | D9: 28 | E9: 0.091503268 | F9: 0.60457516 | G9: A.8 Classify rational and irrational numbers
A10: 6 | B10: Verify | C10: 1 | D10: 15 | E10: 0.049019608 | F10: 0.65359477 | G10: H.3 Identify solutions to inequalities
A11: 7 | B11: Decompose | C11: 1 | D11: 11 | E11: 0.035947712 | F11: 0.68954248 | G11: A.1 Factors
A12: 8 | B12: Compare | C12: 1 | D12: 8 | E12: 0.026143791 | F12: 0.71568627 | G12: A.10 Compare and order rational numbers
A13: 9 | B13: Represent -> Constrain | C13: 2 | D13: 8 | E13: 0.026143791 | F13: 0.74183007 | G13: G.1 Model and solve equations using algebra tiles
A14: 10 | B14: Transform -> Represent | C14: 2 | D14: 8 | E14: 0.026143791 | F14: 0.76797386 | G14: J.10 Complete a function table from an equation
A15: 11 | B15: Represent -> Measure | C15: 2 | D15: 6 | E15: 0.019607843 | F15: 0.7875817 | G15: I.1 Interpret bar graphs, line graphs and histograms
A16: 12 | B16: Compare -> Measure | C16: 2 | D16: 5 | E16: 0.016339869 | F16: 0.80392157 | G16: Y.10 Area and perimeter of similar figures
... A46: 42 | B46: Compose -> Transform -> Represent | C46: 3 | D46: 1 | E46: 0.0032679739 | F46: 1 | G46: FF.10 Compositions of congruence transformations: graph the image
A48: Curriculum skills | B48: 306
A49: Distinct pipelines | B49: 42
A50: Primitives in vocabulary | B50: 10
A51: Mean pipeline length | B51: 1.3
A52: Median pipeline length | B52: 1
A53: Longest pipeline | B53: 3
A54: Skills needing ONE primitive (atomic) | B54: 222
A55: Skills needing a 2-step pipeline | B55: 75
A56: Skills needing a 3-step pipeline | B56: 9
A57: Skills covered by the top 12 pipelines | B57: 246

Sheet Type Check
A1: Falsification test - do the pipelines type-check?
A2: If primitives are real typed operations, every step's output must be a legal input to the next step. This test can fail. It did not.
A5: The rule being tested
A6: For each pipeline step N, the output type of step N must appear in the accepted-input set of step N+1. A single violation would mean at least one primitive is mis-defined.
A8: Result
A9: Pipelines checked: 306
A10: Type errors found: 0
A12: Two predictions the type system made BEFORE the data was examined
A13: 1. Verify returns Boolean. Nothing consumes a Boolean, so Verify must always be the LAST step. Observed: 17 uses, 17 of them final, 0 mid-pipeline. Prediction held.
A14: 2. Identify returns Category. Nothing downstream consumes a Category, so Identify must also be terminal. Observed: 35 uses, 35 of them final, 0 mid-pipeline. Prediction held.
A15: These were not enforced during classification. Each skill was classified on its own reasoning, then the pattern was measured afterwards. That is what makes it evidence rather than bookkeeping.
A17: Three input types were widened during the check, each for a stated reason
... A24: A pipeline requiring Verify or Identify to feed a later step, with no way to rewrite it. That would show the primitive returns something richer than a verdict or a label - meaning it is not one operation but several.

Sheet Category x Primitive
A1: Does each traditional category collapse onto a few primitives?
A2: Counts every appearance of a primitive at any pipeline step within each IXL category.
A4: IXL category | B4: Skills | C4: Identify | D4: Represent | E4: Transform | F4: Compare | G4: Compose | H4: Decompose | I4: Constrain | J4: Measure | K4: Generalize | L4: Verify | M4: Distinct primitives
A5: A. Numbers | B5: =COUNTIF('Classification Matrix'!$D$2:$D$307,"A") | C5: =COUNTIFS('Classification Matrix'!$D$2:$D$307,"A",'Classification Matrix'!$G$2:$G$307,C$4)+COUNTIFS('Classification Matrix'!$D$2:$D$307,"A",'Classification Matrix'!$H$2:$H$307,C$4)+COUNTIFS('Classification Matrix'!$D$2:$D$307,"A",'Classification Matrix'!$I$2:$I$307,C$4) | D5: =COUNTIFS('Classification Matrix'!$D$2:$D$307,"A",'Classification Matrix'!$G$2:$G$307,D$4)+COUNTIFS('Classification Matrix'!$D$2:$D$307,"A",'Classification Matrix'!$H$2:$H$307,D$4)+COUNTIFS('Classification Matrix'!$D$2:$D$307,"A",'Classification Matrix'!$I$2:$I$307,D$4) | E5: =COUNTIFS('Classification Matrix'!$D$2:$D$307,"A",'Classification Matrix'!$G$2:$G$307,E$4)+COUNTIFS('Classification Matrix'!$D$2:$D$307,"A",'Classification Matrix'!$H$2:$H$307,E$4)+COUNTIFS('Classification Matrix'!$D$2:$D$307,"A",'Classification Matrix'!$I$2:$I$307,E$4) | F5: =COUNTIFS('Classification Matrix'!$D$2:$D$307,"A",'Classification Matrix'!$G$2:$G$307,F$4)+COUNTIFS('Classification Matrix'!$D$2:$D$307,"A",'Classification Matrix'!$H$2:$H$307,F$4)+COUNTIFS('Classification Matrix'!$D$2:$D$307,"A",'Classification Matrix'!$I$2:$I$307,F$4) | G5: =COUNTIFS('Classification Matrix'!$D$2:$D$307,"A",'Classification Matrix'!$G$2:$G$307,G$4)+COUNTIFS('Classification Matrix'!$D$2:$D$307,"A",'Classification Matrix'!$H$2:$H$307,G$4)+COUNTIFS('Classification Matrix'!$D$2:$D$307,"A",'Classification Matrix'!$I$2:$I$307,G$4) | H5: =COUNTIFS('Classification Matrix'!$D$2:$D$307,"A",'Classification Matrix'!$G$2:$G$307,H$4)+COUNTIFS('Classification Matrix'!$D$2:$D$307,"A",'Classification Matrix'!$H$2:$H$307,H$4)+COUNTIFS('Classification Matrix'!$D$2:$D$307,"A",'Classification Matrix'!$I$2:$I$307,H$4) | I5: =COUNTIFS('Classification Matrix'!$D$2:$D$307,"A",'Classification Matrix'!$G$2:$G$307,I$4)+COUNTIFS('Classification Matrix'!$D$2:$D$307,"A",'Classification Matrix'!$H$2:$H$307,I$4)+COUNTIFS('Classification Matrix'!$D$2:$D$307,"A",'Classification Matrix'!$I$2:$I$307,I$4) | J5: =COUNTIFS('Classification Matrix'!$D$2:$D$307,"A",'Classification Matrix'!$G$2:$G$307,J$4)+COUNTIFS('Classification Matrix'!$D$2:$D$307,"A",'Classification Matrix'!$H$2:$H$307,J$4)+COUNTIFS('Classification Matrix'!$D$2:$D$307,"A",'Classification Matrix'!$I$2:$I$307,J$4) | ... L5: =COUNTIFS('Classification Matrix'!$D$2:$D$307,"A",'Classification Matrix'!$G$2:$G$307,L$4)+COUNTIFS('Classification Matrix'!$D$2:$D$307,"A",'Classification Matrix'!$H$2:$H$307,L$4)+COUNTIFS('Classification Matrix'!$D$2:$D$307,"A",'Classification Matrix'!$I$2:$I$307,L$4) | M5: =COUNTIF(C5:L5,">0")
A6: B. Exponents | B6: =COUNTIF('Classification Matrix'!$D$2:$D$307,"B") | C6: =COUNTIFS('Classification Matrix'!$D$2:$D$307,"B",'Classification Matrix'!$G$2:$G$307,C$4)+COUNTIFS('Classification Matrix'!$D$2:$D$307,"B",'Classification Matrix'!$H$2:$H$307,C$4)+COUNTIFS('Classification Matrix'!$D$2:$D$307,"B",'Classification Matrix'!$I$2:$I$307,C$4) | D6: =COUNTIFS('Classification Matrix'!$D$2:$D$307,"B",'Classification Matrix'!$G$2:$G$307,D$4)+COUNTIFS('Classification Matrix'!$D$2:$D$307,"B",'Classification Matrix'!$H$2:$H$307,D$4)+COUNTIFS('Classification Matrix'!$D$2:$D$307,"B",'Classification Matrix'!$I$2:$I$307,D$4) | E6: =COUNTIFS('Classification Matrix'!$D$2:$D$307,"B",'Classification Matrix'!$G$2:$G$307,E$4)+COUNTIFS('Classification Matrix'!$D$2:$D$307,"B",'Classification Matrix'!$H$2:$H$307,E$4)+COUNTIFS('Classification Matrix'!$D$2:$D$307,"B",'Classification Matrix'!$I$2:$I$307,E$4) | F6: =COUNTIFS('Classification Matrix'!$D$2:$D$307,"B",'Classification Matrix'!$G$2:$G$307,F$4)+COUNTIFS('Classification Matrix'!$D$2:$D$307,"B",'Classification Matrix'!$H$2:$H$307,F$4)+COUNTIFS('Classification Matrix'!$D$2:$D$307,"B",'Classification Matrix'!$I$2:$I$307,F$4) | G6: =COUNTIFS('Classification Matrix'!$D$2:$D$307,"B",'Classification Matrix'!$G$2:$G$307,G$4)+COUNTIFS('Classification Matrix'!$D$2:$D$307,"B",'Classification Matrix'!$H$2:$H$307,G$4)+COUNTIFS('Classification Matrix'!$D$2:$D$307,"B",'Classification Matrix'!$I$2:$I$307,G$4) | H6: =COUNTIFS('Classification Matrix'!$D$2:$D$307,"B",'Classification Matrix'!$G$2:$G$307,H$4)+COUNTIFS('Classification Matrix'!$D$2:$D$307,"B",'Classification Matrix'!$H$2:$H$307,H$4)+COUNTIFS('Classification Matrix'!$D$2:$D$307,"B",'Classification Matrix'!$I$2:$I$307,H$4) | I6: =COUNTIFS('Classification Matrix'!$D$2:$D$307,"B",'Classification Matrix'!$G$2:$G$307,I$4)+COUNTIFS('Classification Matrix'!$D$2:$D$307,"B",'Classification Matrix'!$H$2:$H$307,I$4)+COUNTIFS('Classification Matrix'!$D$2:$D$307,"B",'Classification Matrix'!$I$2:$I$307,I$4) | J6: =COUNTIFS('Classification Matrix'!$D$2:$D$307,"B",'Classification Matrix'!$G$2:$G$307,J$4)+COUNTIFS('Classification Matrix'!$D$2:$D$307,"B",'Classification Matrix'!$H$2:$H$307,J$4)+COUNTIFS('Classification Matrix'!$D$2:$D$307,"B",'Classification Matrix'!$I$2:$I$307,J$4) | ... L6: =COUNTIFS('Classification Matrix'!$D$2:$D$307,"B",'Classification Matrix'!$G$2:$G$307,L$4)+COUNTIFS('Classification Matrix'!$D$2:$D$307,"B",'Classification Matrix'!$H$2:$H$307,L$4)+COUNTIFS('Classification Matrix'!$D$2:$D$307,"B",'Classification Matrix'!$I$2:$I$307,L$4) | M6: =COUNTIF(C6:L6,">0")
A7: C. Scientific notation | B7: =COUNTIF('Classification Matrix'!$D$2:$D$307,"C") | C7: =COUNTIFS('Classification Matrix'!$D$2:$D$307,"C",'Classification Matrix'!$G$2:$G$307,C$4)+COUNTIFS('Classification Matrix'!$D$2:$D$307,"C",'Classification Matrix'!$H$2:$H$307,C$4)+COUNTIFS('Classification Matrix'!$D$2:$D$307,"C",'Classification Matrix'!$I$2:$I$307,C$4) | D7: =COUNTIFS('Classification Matrix'!$D$2:$D$307,"C",'Classification Matrix'!$G$2:$G$307,D$4)+COUNTIFS('Classification Matrix'!$D$2:$D$307,"C",'Classification Matrix'!$H$2:$H$307,D$4)+COUNTIFS('Classification Matrix'!$D$2:$D$307,"C",'Classification Matrix'!$I$2:$I$307,D$4) | E7: =COUNTIFS('Classification Matrix'!$D$2:$D$307,"C",'Classification Matrix'!$G$2:$G$307,E$4)+COUNTIFS('Classification Matrix'!$D$2:$D$307,"C",'Classification Matrix'!$H$2:$H$307,E$4)+COUNTIFS('Classification Matrix'!$D$2:$D$307,"C",'Classification Matrix'!$I$2:$I$307,E$4) | F7: =COUNTIFS('Classification Matrix'!$D$2:$D$307,"C",'Classification Matrix'!$G$2:$G$307,F$4)+COUNTIFS('Classification Matrix'!$D$2:$D$307,"C",'Classification Matrix'!$H$2:$H$307,F$4)+COUNTIFS('Classification Matrix'!$D$2:$D$307,"C",'Classification Matrix'!$I$2:$I$307,F$4) | G7: =COUNTIFS('Classification Matrix'!$D$2:$D$307,"C",'Classification Matrix'!$G$2:$G$307,G$4)+COUNTIFS('Classification Matrix'!$D$2:$D$307,"C",'Classification Matrix'!$H$2:$H$307,G$4)+COUNTIFS('Classification Matrix'!$D$2:$D$307,"C",'Classification Matrix'!$I$2:$I$307,G$4) | H7: =COUNTIFS('Classification Matrix'!$D$2:$D$307,"C",'Classification Matrix'!$G$2:$G$307,H$4)+COUNTIFS('Classification Matrix'!$D$2:$D$307,"C",'Classification Matrix'!$H$2:$H$307,H$4)+COUNTIFS('Classification Matrix'!$D$2:$D$307,"C",'Classification Matrix'!$I$2:$I$307,H$4) | I7: =COUNTIFS('Classification Matrix'!$D$2:$D$307,"C",'Classification Matrix'!$G$2:$G$307,I$4)+COUNTIFS('Classification Matrix'!$D$2:$D$307,"C",'Classification Matrix'!$H$2:$H$307,I$4)+COUNTIFS('Classification Matrix'!$D$2:$D$307,"C",'Classification Matrix'!$I$2:$I$307,I$4) | J7: =COUNTIFS('Classification Matrix'!$D$2:$D$307,"C",'Classification Matrix'!$G$2:$G$307,J$4)+COUNTIFS('Classification Matrix'!$D$2:$D$307,"C",'Classification Matrix'!$H$2:$H$307,J$4)+COUNTIFS('Classification Matrix'!$D$2:$D$307,"C",'Classification Matrix'!$I$2:$I$307,J$4) | ... L7: =COUNTIFS('Classification Matrix'!$D$2:$D$307,"C",'Classification Matrix'!$G$2:$G$307,L$4)+COUNTIFS('Classification Matrix'!$D$2:$D$307,"C",'Classification Matrix'!$H$2:$H$307,L$4)+COUNTIFS('Classification Matrix'!$D$2:$D$307,"C",'Classification Matrix'!$I$2:$I$307,L$4) | M7: =COUNTIF(C7:L7,">0")
A8: D. Radical expressions | B8: =COUNTIF('Classification Matrix'!$D$2:$D$307,"D") | C8: =COUNTIFS('Classification Matrix'!$D$2:$D$307,"D",'Classification Matrix'!$G$2:$G$307,C$4)+COUNTIFS('Classification Matrix'!$D$2:$D$307,"D",'Classification Matrix'!$H$2:$H$307,C$4)+COUNTIFS('Classification Matrix'!$D$2:$D$307,"D",'Classification Matrix'!$I$2:$I$307,C$4) | D8: =COUNTIFS('Classification Matrix'!$D$2:$D$307,"D",'Classification Matrix'!$G$2:$G$307,D$4)+COUNTIFS('Classification Matrix'!$D$2:$D$307,"D",'Classification Matrix'!$H$2:$H$307,D$4)+COUNTIFS('Classification Matrix'!$D$2:$D$307,"D",'Classification Matrix'!$I$2:$I$307,D$4) | E8: =COUNTIFS('Classification Matrix'!$D$2:$D$307,"D",'Classification Matrix'!$G$2:$G$307,E$4)+COUNTIFS('Classification Matrix'!$D$2:$D$307,"D",'Classification Matrix'!$H$2:$H$307,E$4)+COUNTIFS('Classification Matrix'!$D$2:$D$307,"D",'Classification Matrix'!$I$2:$I$307,E$4) | F8: =COUNTIFS('Classification Matrix'!$D$2:$D$307,"D",'Classification Matrix'!$G$2:$G$307,F$4)+COUNTIFS('Classification Matrix'!$D$2:$D$307,"D",'Classification Matrix'!$H$2:$H$307,F$4)+COUNTIFS('Classification Matrix'!$D$2:$D$307,"D",'Classification Matrix'!$I$2:$I$307,F$4) | G8: =COUNTIFS('Classification Matrix'!$D$2:$D$307,"D",'Classification Matrix'!$G$2:$G$307,G$4)+COUNTIFS('Classification Matrix'!$D$2:$D$307,"D",'Classification Matrix'!$H$2:$H$307,G$4)+COUNTIFS('Classification Matrix'!$D$2:$D$307,"D",'Classification Matrix'!$I$2:$I$307,G$4) | H8: =COUNTIFS('Classification Matrix'!$D$2:$D$307,"D",'Classification Matrix'!$G$2:$G$307,H$4)+COUNTIFS('Classification Matrix'!$D$2:$D$307,"D",'Classification Matrix'!$H$2:$H$307,H$4)+COUNTIFS('Classification Matrix'!$D$2:$D$307,"D",'Classification Matrix'!$I$2:$I$307,H$4) | I8: =COUNTIFS('Classification Matrix'!$D$2:$D$307,"D",'Classification Matrix'!$G$2:$G$307,I$4)+COUNTIFS('Classification Matrix'!$D$2:$D$307,"D",'Classification Matrix'!$H$2:$H$307,I$4)+COUNTIFS('Classification Matrix'!$D$2:$D$307,"D",'Classification Matrix'!$I$2:$I$307,I$4) | J8: =COUNTIFS('Classification Matrix'!$D$2:$D$307,"D",'Classification Matrix'!$G$2:$G$307,J$4)+COUNTIFS('Classification Matrix'!$D$2:$D$307,"D",'Classification Matrix'!$H$2:$H$307,J$4)+COUNTIFS('Classification Matrix'!$D$2:$D$307,"D",'Classification Matrix'!$I$2:$I$307,J$4) | ... L8: =COUNTIFS('Classification Matrix'!$D$2:$D$307,"D",'Classification Matrix'!$G$2:$G$307,L$4)+COUNTIFS('Classification Matrix'!$D$2:$D$307,"D",'Classification Matrix'!$H$2:$H$307,L$4)+COUNTIFS('Classification Matrix'!$D$2:$D$307,"D",'Classification Matrix'!$I$2:$I$307,L$4) | M8: =COUNTIF(C8:L8,">0")
A9: E. Rational exponents | B9: =COUNTIF('Classification Matrix'!$D$2:$D$307,"E") | C9: =COUNTIFS('Classification Matrix'!$D$2:$D$307,"E",'Classification Matrix'!$G$2:$G$307,C$4)+COUNTIFS('Classification Matrix'!$D$2:$D$307,"E",'Classification Matrix'!$H$2:$H$307,C$4)+COUNTIFS('Classification Matrix'!$D$2:$D$307,"E",'Classification Matrix'!$I$2:$I$307,C$4) | D9: =COUNTIFS('Classification Matrix'!$D$2:$D$307,"E",'Classification Matrix'!$G$2:$G$307,D$4)+COUNTIFS('Classification Matrix'!$D$2:$D$307,"E",'Classification Matrix'!$H$2:$H$307,D$4)+COUNTIFS('Classification Matrix'!$D$2:$D$307,"E",'Classification Matrix'!$I$2:$I$307,D$4) | E9: =COUNTIFS('Classification Matrix'!$D$2:$D$307,"E",'Classification Matrix'!$G$2:$G$307,E$4)+COUNTIFS('Classification Matrix'!$D$2:$D$307,"E",'Classification Matrix'!$H$2:$H$307,E$4)+COUNTIFS('Classification Matrix'!$D$2:$D$307,"E",'Classification Matrix'!$I$2:$I$307,E$4) | F9: =COUNTIFS('Classification Matrix'!$D$2:$D$307,"E",'Classification Matrix'!$G$2:$G$307,F$4)+COUNTIFS('Classification Matrix'!$D$2:$D$307,"E",'Classification Matrix'!$H$2:$H$307,F$4)+COUNTIFS('Classification Matrix'!$D$2:$D$307,"E",'Classification Matrix'!$I$2:$I$307,F$4) | G9: =COUNTIFS('Classification Matrix'!$D$2:$D$307,"E",'Classification Matrix'!$G$2:$G$307,G$4)+COUNTIFS('Classification Matrix'!$D$2:$D$307,"E",'Classification Matrix'!$H$2:$H$307,G$4)+COUNTIFS('Classification Matrix'!$D$2:$D$307,"E",'Classification Matrix'!$I$2:$I$307,G$4) | H9: =COUNTIFS('Classification Matrix'!$D$2:$D$307,"E",'Classification Matrix'!$G$2:$G$307,H$4)+COUNTIFS('Classification Matrix'!$D$2:$D$307,"E",'Classification Matrix'!$H$2:$H$307,H$4)+COUNTIFS('Classification Matrix'!$D$2:$D$307,"E",'Classification Matrix'!$I$2:$I$307,H$4) | I9: =COUNTIFS('Classification Matrix'!$D$2:$D$307,"E",'Classification Matrix'!$G$2:$G$307,I$4)+COUNTIFS('Classification Matrix'!$D$2:$D$307,"E",'Classification Matrix'!$H$2:$H$307,I$4)+COUNTIFS('Classification Matrix'!$D$2:$D$307,"E",'Classification Matrix'!$I$2:$I$307,I$4) | J9: =COUNTIFS('Classification Matrix'!$D$2:$D$307,"E",'Classification Matrix'!$G$2:$G$307,J$4)+COUNTIFS('Classification Matrix'!$D$2:$D$307,"E",'Classification Matrix'!$H$2:$H$307,J$4)+COUNTIFS('Classification Matrix'!$D$2:$D$307,"E",'Classification Matrix'!$I$2:$I$307,J$4) | ... L9: =COUNTIFS('Classification Matrix'!$D$2:$D$307,"E",'Classification Matrix'!$G$2:$G$307,L$4)+COUNTIFS('Classification Matrix'!$D$2:$D$307,"E",'Classification Matrix'!$H$2:$H$307,L$4)+COUNTIFS('Classification Matrix'!$D$2:$D$307,"E",'Classification Matrix'!$I$2:$I$307,L$4) | M9: =COUNTIF(C9:L9,">0")
A10: F. Coordinate plane | B10: =COUNTIF('Classification Matrix'!$D$2:$D$307,"F") | C10: =COUNTIFS('Classification Matrix'!$D$2:$D$307,"F",'Classification Matrix'!$G$2:$G$307,C$4)+COUNTIFS('Classification Matrix'!$D$2:$D$307,"F",'Classification Matrix'!$H$2:$H$307,C$4)+COUNTIFS('Classification Matrix'!$D$2:$D$307,"F",'Classification Matrix'!$I$2:$I$307,C$4) | D10: =COUNTIFS('Classification Matrix'!$D$2:$D$307,"F",'Classification Matrix'!$G$2:$G$307,D$4)+COUNTIFS('Classification Matrix'!$D$2:$D$307,"F",'Classification Matrix'!$H$2:$H$307,D$4)+COUNTIFS('Classification Matrix'!$D$2:$D$307,"F",'Classification Matrix'!$I$2:$I$307,D$4) | E10: =COUNTIFS('Classification Matrix'!$D$2:$D$307,"F",'Classification Matrix'!$G$2:$G$307,E$4)+COUNTIFS('Classification Matrix'!$D$2:$D$307,"F",'Classification Matrix'!$H$2:$H$307,E$4)+COUNTIFS('Classification Matrix'!$D$2:$D$307,"F",'Classification Matrix'!$I$2:$I$307,E$4) | F10: =COUNTIFS('Classification Matrix'!$D$2:$D$307,"F",'Classification Matrix'!$G$2:$G$307,F$4)+COUNTIFS('Classification Matrix'!$D$2:$D$307,"F",'Classification Matrix'!$H$2:$H$307,F$4)+COUNTIFS('Classification Matrix'!$D$2:$D$307,"F",'Classification Matrix'!$I$2:$I$307,F$4) | G10: =COUNTIFS('Classification Matrix'!$D$2:$D$307,"F",'Classification Matrix'!$G$2:$G$307,G$4)+COUNTIFS('Classification Matrix'!$D$2:$D$307,"F",'Classification Matrix'!$H$2:$H$307,G$4)+COUNTIFS('Classification Matrix'!$D$2:$D$307,"F",'Classification Matrix'!$I$2:$I$307,G$4) | H10: =COUNTIFS('Classification Matrix'!$D$2:$D$307,"F",'Classification Matrix'!$G$2:$G$307,H$4)+COUNTIFS('Classification Matrix'!$D$2:$D$307,"F",'Classification Matrix'!$H$2:$H$307,H$4)+COUNTIFS('Classification Matrix'!$D$2:$D$307,"F",'Classification Matrix'!$I$2:$I$307,H$4) | I10: =COUNTIFS('Classification Matrix'!$D$2:$D$307,"F",'Classification Matrix'!$G$2:$G$307,I$4)+COUNTIFS('Classification Matrix'!$D$2:$D$307,"F",'Classification Matrix'!$H$2:$H$307,I$4)+COUNTIFS('Classification Matrix'!$D$2:$D$307,"F",'Classification Matrix'!$I$2:$I$307,I$4) | J10: =COUNTIFS('Classification Matrix'!$D$2:$D$307,"F",'Classification Matrix'!$G$2:$G$307,J$4)+COUNTIFS('Classification Matrix'!$D$2:$D$307,"F",'Classification Matrix'!$H$2:$H$307,J$4)+COUNTIFS('Classification Matrix'!$D$2:$D$307,"F",'Classification Matrix'!$I$2:$I$307,J$4) | ... L10: =COUNTIFS('Classification Matrix'!$D$2:$D$307,"F",'Classification Matrix'!$G$2:$G$307,L$4)+COUNTIFS('Classification Matrix'!$D$2:$D$307,"F",'Classification Matrix'!$H$2:$H$307,L$4)+COUNTIFS('Classification Matrix'!$D$2:$D$307,"F",'Classification Matrix'!$I$2:$I$307,L$4) | M10: =COUNTIF(C10:L10,">0")
A11: G. Solve equations | B11: =COUNTIF('Classification Matrix'!$D$2:$D$307,"G") | C11: =COUNTIFS('Classification Matrix'!$D$2:$D$307,"G",'Classification Matrix'!$G$2:$G$307,C$4)+COUNTIFS('Classification Matrix'!$D$2:$D$307,"G",'Classification Matrix'!$H$2:$H$307,C$4)+COUNTIFS('Classification Matrix'!$D$2:$D$307,"G",'Classification Matrix'!$I$2:$I$307,C$4) | D11: =COUNTIFS('Classification Matrix'!$D$2:$D$307,"G",'Classification Matrix'!$G$2:$G$307,D$4)+COUNTIFS('Classification Matrix'!$D$2:$D$307,"G",'Classification Matrix'!$H$2:$H$307,D$4)+COUNTIFS('Classification Matrix'!$D$2:$D$307,"G",'Classification Matrix'!$I$2:$I$307,D$4) | E11: =COUNTIFS('Classification Matrix'!$D$2:$D$307,"G",'Classification Matrix'!$G$2:$G$307,E$4)+COUNTIFS('Classification Matrix'!$D$2:$D$307,"G",'Classification Matrix'!$H$2:$H$307,E$4)+COUNTIFS('Classification Matrix'!$D$2:$D$307,"G",'Classification Matrix'!$I$2:$I$307,E$4) | F11: =COUNTIFS('Classification Matrix'!$D$2:$D$307,"G",'Classification Matrix'!$G$2:$G$307,F$4)+COUNTIFS('Classification Matrix'!$D$2:$D$307,"G",'Classification Matrix'!$H$2:$H$307,F$4)+COUNTIFS('Classification Matrix'!$D$2:$D$307,"G",'Classification Matrix'!$I$2:$I$307,F$4) | G11: =COUNTIFS('Classification Matrix'!$D$2:$D$307,"G",'Classification Matrix'!$G$2:$G$307,G$4)+COUNTIFS('Classification Matrix'!$D$2:$D$307,"G",'Classification Matrix'!$H$2:$H$307,G$4)+COUNTIFS('Classification Matrix'!$D$2:$D$307,"G",'Classification Matrix'!$I$2:$I$307,G$4) | H11: =COUNTIFS('Classification Matrix'!$D$2:$D$307,"G",'Classification Matrix'!$G$2:$G$307,H$4)+COUNTIFS('Classification Matrix'!$D$2:$D$307,"G",'Classification Matrix'!$H$2:$H$307,H$4)+COUNTIFS('Classification Matrix'!$D$2:$D$307,"G",'Classification Matrix'!$I$2:$I$307,H$4) | I11: =COUNTIFS('Classification Matrix'!$D$2:$D$307,"G",'Classification Matrix'!$G$2:$G$307,I$4)+COUNTIFS('Classification Matrix'!$D$2:$D$307,"G",'Classification Matrix'!$H$2:$H$307,I$4)+COUNTIFS('Classification Matrix'!$D$2:$D$307,"G",'Classification Matrix'!$I$2:$I$307,I$4) | J11: =COUNTIFS('Classification Matrix'!$D$2:$D$307,"G",'Classification Matrix'!$G$2:$G$307,J$4)+COUNTIFS('Classification Matrix'!$D$2:$D$307,"G",'Classification Matrix'!$H$2:$H$307,J$4)+COUNTIFS('Classification Matrix'!$D$2:$D$307,"G",'Classification Matrix'!$I$2:$I$307,J$4) | ... L11: =COUNTIFS('Classification Matrix'!$D$2:$D$307,"G",'Classification Matrix'!$G$2:$G$307,L$4)+COUNTIFS('Classification Matrix'!$D$2:$D$307,"G",'Classification Matrix'!$H$2:$H$307,L$4)+COUNTIFS('Classification Matrix'!$D$2:$D$307,"G",'Classification Matrix'!$I$2:$I$307,L$4) | M11: =COUNTIF(C11:L11,">0")
A12: H. Single-variable inequalities | B12: =COUNTIF('Classification Matrix'!$D$2:$D$307,"H") | C12: =COUNTIFS('Classification Matrix'!$D$2:$D$307,"H",'Classification Matrix'!$G$2:$G$307,C$4)+COUNTIFS('Classification Matrix'!$D$2:$D$307,"H",'Classification Matrix'!$H$2:$H$307,C$4)+COUNTIFS('Classification Matrix'!$D$2:$D$307,"H",'Classification Matrix'!$I$2:$I$307,C$4) | D12: =COUNTIFS('Classification Matrix'!$D$2:$D$307,"H",'Classification Matrix'!$G$2:$G$307,D$4)+COUNTIFS('Classification Matrix'!$D$2:$D$307,"H",'Classification Matrix'!$H$2:$H$307,D$4)+COUNTIFS('Classification Matrix'!$D$2:$D$307,"H",'Classification Matrix'!$I$2:$I$307,D$4) | E12: =COUNTIFS('Classification Matrix'!$D$2:$D$307,"H",'Classification Matrix'!$G$2:$G$307,E$4)+COUNTIFS('Classification Matrix'!$D$2:$D$307,"H",'Classification Matrix'!$H$2:$H$307,E$4)+COUNTIFS('Classification Matrix'!$D$2:$D$307,"H",'Classification Matrix'!$I$2:$I$307,E$4) | F12: =COUNTIFS('Classification Matrix'!$D$2:$D$307,"H",'Classification Matrix'!$G$2:$G$307,F$4)+COUNTIFS('Classification Matrix'!$D$2:$D$307,"H",'Classification Matrix'!$H$2:$H$307,F$4)+COUNTIFS('Classification Matrix'!$D$2:$D$307,"H",'Classification Matrix'!$I$2:$I$307,F$4) | G12: =COUNTIFS('Classification Matrix'!$D$2:$D$307,"H",'Classification Matrix'!$G$2:$G$307,G$4)+COUNTIFS('Classification Matrix'!$D$2:$D$307,"H",'Classification Matrix'!$H$2:$H$307,G$4)+COUNTIFS('Classification Matrix'!$D$2:$D$307,"H",'Classification Matrix'!$I$2:$I$307,G$4) | H12: =COUNTIFS('Classification Matrix'!$D$2:$D$307,"H",'Classification Matrix'!$G$2:$G$307,H$4)+COUNTIFS('Classification Matrix'!$D$2:$D$307,"H",'Classification Matrix'!$H$2:$H$307,H$4)+COUNTIFS('Classification Matrix'!$D$2:$D$307,"H",'Classification Matrix'!$I$2:$I$307,H$4) | I12: =COUNTIFS('Classification Matrix'!$D$2:$D$307,"H",'Classification Matrix'!$G$2:$G$307,I$4)+COUNTIFS('Classification Matrix'!$D$2:$D$307,"H",'Classification Matrix'!$H$2:$H$307,I$4)+COUNTIFS('Classification Matrix'!$D$2:$D$307,"H",'Classification Matrix'!$I$2:$I$307,I$4) | J12: =COUNTIFS('Classification Matrix'!$D$2:$D$307,"H",'Classification Matrix'!$G$2:$G$307,J$4)+COUNTIFS('Classification Matrix'!$D$2:$D$307,"H",'Classification Matrix'!$H$2:$H$307,J$4)+COUNTIFS('Classification Matrix'!$D$2:$D$307,"H",'Classification Matrix'!$I$2:$I$307,J$4) | ... L12: =COUNTIFS('Classification Matrix'!$D$2:$D$307,"H",'Classification Matrix'!$G$2:$G$307,L$4)+COUNTIFS('Classification Matrix'!$D$2:$D$307,"H",'Classification Matrix'!$H$2:$H$307,L$4)+COUNTIFS('Classification Matrix'!$D$2:$D$307,"H",'Classification Matrix'!$I$2:$I$307,L$4) | M12: =COUNTIF(C12:L12,">0")
A13: I. Data and graphs | B13: =COUNTIF('Classification Matrix'!$D$2:$D$307,"I") | C13: =COUNTIFS('Classification Matrix'!$D$2:$D$307,"I",'Classification Matrix'!$G$2:$G$307,C$4)+COUNTIFS('Classification Matrix'!$D$2:$D$307,"I",'Classification Matrix'!$H$2:$H$307,C$4)+COUNTIFS('Classification Matrix'!$D$2:$D$307,"I",'Classification Matrix'!$I$2:$I$307,C$4) | D13: =COUNTIFS('Classification Matrix'!$D$2:$D$307,"I",'Classification Matrix'!$G$2:$G$307,D$4)+COUNTIFS('Classification Matrix'!$D$2:$D$307,"I",'Classification Matrix'!$H$2:$H$307,D$4)+COUNTIFS('Classification Matrix'!$D$2:$D$307,"I",'Classification Matrix'!$I$2:$I$307,D$4) | E13: =COUNTIFS('Classification Matrix'!$D$2:$D$307,"I",'Classification Matrix'!$G$2:$G$307,E$4)+COUNTIFS('Classification Matrix'!$D$2:$D$307,"I",'Classification Matrix'!$H$2:$H$307,E$4)+COUNTIFS('Classification Matrix'!$D$2:$D$307,"I",'Classification Matrix'!$I$2:$I$307,E$4) | F13: =COUNTIFS('Classification Matrix'!$D$2:$D$307,"I",'Classification Matrix'!$G$2:$G$307,F$4)+COUNTIFS('Classification Matrix'!$D$2:$D$307,"I",'Classification Matrix'!$H$2:$H$307,F$4)+COUNTIFS('Classification Matrix'!$D$2:$D$307,"I",'Classification Matrix'!$I$2:$I$307,F$4) | G13: =COUNTIFS('Classification Matrix'!$D$2:$D$307,"I",'Classification Matrix'!$G$2:$G$307,G$4)+COUNTIFS('Classification Matrix'!$D$2:$D$307,"I",'Classification Matrix'!$H$2:$H$307,G$4)+COUNTIFS('Classification Matrix'!$D$2:$D$307,"I",'Classification Matrix'!$I$2:$I$307,G$4) | H13: =COUNTIFS('Classification Matrix'!$D$2:$D$307,"I",'Classification Matrix'!$G$2:$G$307,H$4)+COUNTIFS('Classification Matrix'!$D$2:$D$307,"I",'Classification Matrix'!$H$2:$H$307,H$4)+COUNTIFS('Classification Matrix'!$D$2:$D$307,"I",'Classification Matrix'!$I$2:$I$307,H$4) | I13: =COUNTIFS('Classification Matrix'!$D$2:$D$307,"I",'Classification Matrix'!$G$2:$G$307,I$4)+COUNTIFS('Classification Matrix'!$D$2:$D$307,"I",'Classification Matrix'!$H$2:$H$307,I$4)+COUNTIFS('Classification Matrix'!$D$2:$D$307,"I",'Classification Matrix'!$I$2:$I$307,I$4) | J13: =COUNTIFS('Classification Matrix'!$D$2:$D$307,"I",'Classification Matrix'!$G$2:$G$307,J$4)+COUNTIFS('Classification Matrix'!$D$2:$D$307,"I",'Classification Matrix'!$H$2:$H$307,J$4)+COUNTIFS('Classification Matrix'!$D$2:$D$307,"I",'Classification Matrix'!$I$2:$I$307,J$4) | ... L13: =COUNTIFS('Classification Matrix'!$D$2:$D$307,"I",'Classification Matrix'!$G$2:$G$307,L$4)+COUNTIFS('Classification Matrix'!$D$2:$D$307,"I",'Classification Matrix'!$H$2:$H$307,L$4)+COUNTIFS('Classification Matrix'!$D$2:$D$307,"I",'Classification Matrix'!$I$2:$I$307,L$4) | M13: =COUNTIF(C13:L13,">0")
A14: J. Relations and functions | B14: =COUNTIF('Classification Matrix'!$D$2:$D$307,"J") | C14: =COUNTIFS('Classification Matrix'!$D$2:$D$307,"J",'Classification Matrix'!$G$2:$G$307,C$4)+COUNTIFS('Classification Matrix'!$D$2:$D$307,"J",'Classification Matrix'!$H$2:$H$307,C$4)+COUNTIFS('Classification Matrix'!$D$2:$D$307,"J",'Classification Matrix'!$I$2:$I$307,C$4) | D14: =COUNTIFS('Classification Matrix'!$D$2:$D$307,"J",'Classification Matrix'!$G$2:$G$307,D$4)+COUNTIFS('Classification Matrix'!$D$2:$D$307,"J",'Classification Matrix'!$H$2:$H$307,D$4)+COUNTIFS('Classification Matrix'!$D$2:$D$307,"J",'Classification Matrix'!$I$2:$I$307,D$4) | E14: =COUNTIFS('Classification Matrix'!$D$2:$D$307,"J",'Classification Matrix'!$G$2:$G$307,E$4)+COUNTIFS('Classification Matrix'!$D$2:$D$307,"J",'Classification Matrix'!$H$2:$H$307,E$4)+COUNTIFS('Classification Matrix'!$D$2:$D$307,"J",'Classification Matrix'!$I$2:$I$307,E$4) | F14: =COUNTIFS('Classification Matrix'!$D$2:$D$307,"J",'Classification Matrix'!$G$2:$G$307,F$4)+COUNTIFS('Classification Matrix'!$D$2:$D$307,"J",'Classification Matrix'!$H$2:$H$307,F$4)+COUNTIFS('Classification Matrix'!$D$2:$D$307,"J",'Classification Matrix'!$I$2:$I$307,F$4) | G14: =COUNTIFS('Classification Matrix'!$D$2:$D$307,"J",'Classification Matrix'!$G$2:$G$307,G$4)+COUNTIFS('Classification Matrix'!$D$2:$D$307,"J",'Classification Matrix'!$H$2:$H$307,G$4)+COUNTIFS('Classification Matrix'!$D$2:$D$307,"J",'Classification Matrix'!$I$2:$I$307,G$4) | H14: =COUNTIFS('Classification Matrix'!$D$2:$D$307,"J",'Classification Matrix'!$G$2:$G$307,H$4)+COUNTIFS('Classification Matrix'!$D$2:$D$307,"J",'Classification Matrix'!$H$2:$H$307,H$4)+COUNTIFS('Classification Matrix'!$D$2:$D$307,"J",'Classification Matrix'!$I$2:$I$307,H$4) | I14: =COUNTIFS('Classification Matrix'!$D$2:$D$307,"J",'Classification Matrix'!$G$2:$G$307,I$4)+COUNTIFS('Classification Matrix'!$D$2:$D$307,"J",'Classification Matrix'!$H$2:$H$307,I$4)+COUNTIFS('Classification Matrix'!$D$2:$D$307,"J",'Classification Matrix'!$I$2:$I$307,I$4) | J14: =COUNTIFS('Classification Matrix'!$D$2:$D$307,"J",'Classification Matrix'!$G$2:$G$307,J$4)+COUNTIFS('Classification Matrix'!$D$2:$D$307,"J",'Classification Matrix'!$H$2:$H$307,J$4)+COUNTIFS('Classification Matrix'!$D$2:$D$307,"J",'Classification Matrix'!$I$2:$I$307,J$4) | ... L14: =COUNTIFS('Classification Matrix'!$D$2:$D$307,"J",'Classification Matrix'!$G$2:$G$307,L$4)+COUNTIFS('Classification Matrix'!$D$2:$D$307,"J",'Classification Matrix'!$H$2:$H$307,L$4)+COUNTIFS('Classification Matrix'!$D$2:$D$307,"J",'Classification Matrix'!$I$2:$I$307,L$4) | M14: =COUNTIF(C14:L14,">0")
A15: K. Direct and inverse variation | B15: =COUNTIF('Classification Matrix'!$D$2:$D$307,"K") | C15: =COUNTIFS('Classification Matrix'!$D$2:$D$307,"K",'Classification Matrix'!$G$2:$G$307,C$4)+COUNTIFS('Classification Matrix'!$D$2:$D$307,"K",'Classification Matrix'!$H$2:$H$307,C$4)+COUNTIFS('Classification Matrix'!$D$2:$D$307,"K",'Classification Matrix'!$I$2:$I$307,C$4) | D15: =COUNTIFS('Classification Matrix'!$D$2:$D$307,"K",'Classification Matrix'!$G$2:$G$307,D$4)+COUNTIFS('Classification Matrix'!$D$2:$D$307,"K",'Classification Matrix'!$H$2:$H$307,D$4)+COUNTIFS('Classification Matrix'!$D$2:$D$307,"K",'Classification Matrix'!$I$2:$I$307,D$4) | E15: =COUNTIFS('Classification Matrix'!$D$2:$D$307,"K",'Classification Matrix'!$G$2:$G$307,E$4)+COUNTIFS('Classification Matrix'!$D$2:$D$307,"K",'Classification Matrix'!$H$2:$H$307,E$4)+COUNTIFS('Classification Matrix'!$D$2:$D$307,"K",'Classification Matrix'!$I$2:$I$307,E$4) | F15: =COUNTIFS('Classification Matrix'!$D$2:$D$307,"K",'Classification Matrix'!$G$2:$G$307,F$4)+COUNTIFS('Classification Matrix'!$D$2:$D$307,"K",'Classification Matrix'!$H$2:$H$307,F$4)+COUNTIFS('Classification Matrix'!$D$2:$D$307,"K",'Classification Matrix'!$I$2:$I$307,F$4) | G15: =COUNTIFS('Classification Matrix'!$D$2:$D$307,"K",'Classification Matrix'!$G$2:$G$307,G$4)+COUNTIFS('Classification Matrix'!$D$2:$D$307,"K",'Classification Matrix'!$H$2:$H$307,G$4)+COUNTIFS('Classification Matrix'!$D$2:$D$307,"K",'Classification Matrix'!$I$2:$I$307,G$4) | H15: =COUNTIFS('Classification Matrix'!$D$2:$D$307,"K",'Classification Matrix'!$G$2:$G$307,H$4)+COUNTIFS('Classification Matrix'!$D$2:$D$307,"K",'Classification Matrix'!$H$2:$H$307,H$4)+COUNTIFS('Classification Matrix'!$D$2:$D$307,"K",'Classification Matrix'!$I$2:$I$307,H$4) | I15: =COUNTIFS('Classification Matrix'!$D$2:$D$307,"K",'Classification Matrix'!$G$2:$G$307,I$4)+COUNTIFS('Classification Matrix'!$D$2:$D$307,"K",'Classification Matrix'!$H$2:$H$307,I$4)+COUNTIFS('Classification Matrix'!$D$2:$D$307,"K",'Classification Matrix'!$I$2:$I$307,I$4) | J15: =COUNTIFS('Classification Matrix'!$D$2:$D$307,"K",'Classification Matrix'!$G$2:$G$307,J$4)+COUNTIFS('Classification Matrix'!$D$2:$D$307,"K",'Classification Matrix'!$H$2:$H$307,J$4)+COUNTIFS('Classification Matrix'!$D$2:$D$307,"K",'Classification Matrix'!$I$2:$I$307,J$4) | ... L15: =COUNTIFS('Classification Matrix'!$D$2:$D$307,"K",'Classification Matrix'!$G$2:$G$307,L$4)+COUNTIFS('Classification Matrix'!$D$2:$D$307,"K",'Classification Matrix'!$H$2:$H$307,L$4)+COUNTIFS('Classification Matrix'!$D$2:$D$307,"K",'Classification Matrix'!$I$2:$I$307,L$4) | M15: =COUNTIF(C15:L15,">0")
A16: L. Linear functions | B16: =COUNTIF('Classification Matrix'!$D$2:$D$307,"L") | C16: =COUNTIFS('Classification Matrix'!$D$2:$D$307,"L",'Classification Matrix'!$G$2:$G$307,C$4)+COUNTIFS('Classification Matrix'!$D$2:$D$307,"L",'Classification Matrix'!$H$2:$H$307,C$4)+COUNTIFS('Classification Matrix'!$D$2:$D$307,"L",'Classification Matrix'!$I$2:$I$307,C$4) | D16: =COUNTIFS('Classification Matrix'!$D$2:$D$307,"L",'Classification Matrix'!$G$2:$G$307,D$4)+COUNTIFS('Classification Matrix'!$D$2:$D$307,"L",'Classification Matrix'!$H$2:$H$307,D$4)+COUNTIFS('Classification Matrix'!$D$2:$D$307,"L",'Classification Matrix'!$I$2:$I$307,D$4) | E16: =COUNTIFS('Classification Matrix'!$D$2:$D$307,"L",'Classification Matrix'!$G$2:$G$307,E$4)+COUNTIFS('Classification Matrix'!$D$2:$D$307,"L",'Classification Matrix'!$H$2:$H$307,E$4)+COUNTIFS('Classification Matrix'!$D$2:$D$307,"L",'Classification Matrix'!$I$2:$I$307,E$4) | F16: =COUNTIFS('Classification Matrix'!$D$2:$D$307,"L",'Classification Matrix'!$G$2:$G$307,F$4)+COUNTIFS('Classification Matrix'!$D$2:$D$307,"L",'Classification Matrix'!$H$2:$H$307,F$4)+COUNTIFS('Classification Matrix'!$D$2:$D$307,"L",'Classification Matrix'!$I$2:$I$307,F$4) | G16: =COUNTIFS('Classification Matrix'!$D$2:$D$307,"L",'Classification Matrix'!$G$2:$G$307,G$4)+COUNTIFS('Classification Matrix'!$D$2:$D$307,"L",'Classification Matrix'!$H$2:$H$307,G$4)+COUNTIFS('Classification Matrix'!$D$2:$D$307,"L",'Classification Matrix'!$I$2:$I$307,G$4) | H16: =COUNTIFS('Classification Matrix'!$D$2:$D$307,"L",'Classification Matrix'!$G$2:$G$307,H$4)+COUNTIFS('Classification Matrix'!$D$2:$D$307,"L",'Classification Matrix'!$H$2:$H$307,H$4)+COUNTIFS('Classification Matrix'!$D$2:$D$307,"L",'Classification Matrix'!$I$2:$I$307,H$4) | I16: =COUNTIFS('Classification Matrix'!$D$2:$D$307,"L",'Classification Matrix'!$G$2:$G$307,I$4)+COUNTIFS('Classification Matrix'!$D$2:$D$307,"L",'Classification Matrix'!$H$2:$H$307,I$4)+COUNTIFS('Classification Matrix'!$D$2:$D$307,"L",'Classification Matrix'!$I$2:$I$307,I$4) | J16: =COUNTIFS('Classification Matrix'!$D$2:$D$307,"L",'Classification Matrix'!$G$2:$G$307,J$4)+COUNTIFS('Classification Matrix'!$D$2:$D$307,"L",'Classification Matrix'!$H$2:$H$307,J$4)+COUNTIFS('Classification Matrix'!$D$2:$D$307,"L",'Classification Matrix'!$I$2:$I$307,J$4) | ... L16: =COUNTIFS('Classification Matrix'!$D$2:$D$307,"L",'Classification Matrix'!$G$2:$G$307,L$4)+COUNTIFS('Classification Matrix'!$D$2:$D$307,"L",'Classification Matrix'!$H$2:$H$307,L$4)+COUNTIFS('Classification Matrix'!$D$2:$D$307,"L",'Classification Matrix'!$I$2:$I$307,L$4) | M16: =COUNTIF(C16:L16,">0")
A17: M. Systems of linear equations | B17: =COUNTIF('Classification Matrix'!$D$2:$D$307,"M") | C17: =COUNTIFS('Classification Matrix'!$D$2:$D$307,"M",'Classification Matrix'!$G$2:$G$307,C$4)+COUNTIFS('Classification Matrix'!$D$2:$D$307,"M",'Classification Matrix'!$H$2:$H$307,C$4)+COUNTIFS('Classification Matrix'!$D$2:$D$307,"M",'Classification Matrix'!$I$2:$I$307,C$4) | D17: =COUNTIFS('Classification Matrix'!$D$2:$D$307,"M",'Classification Matrix'!$G$2:$G$307,D$4)+COUNTIFS('Classification Matrix'!$D$2:$D$307,"M",'Classification Matrix'!$H$2:$H$307,D$4)+COUNTIFS('Classification Matrix'!$D$2:$D$307,"M",'Classification Matrix'!$I$2:$I$307,D$4) | E17: =COUNTIFS('Classification Matrix'!$D$2:$D$307,"M",'Classification Matrix'!$G$2:$G$307,E$4)+COUNTIFS('Classification Matrix'!$D$2:$D$307,"M",'Classification Matrix'!$H$2:$H$307,E$4)+COUNTIFS('Classification Matrix'!$D$2:$D$307,"M",'Classification Matrix'!$I$2:$I$307,E$4) | F17: =COUNTIFS('Classification Matrix'!$D$2:$D$307,"M",'Classification Matrix'!$G$2:$G$307,F$4)+COUNTIFS('Classification Matrix'!$D$2:$D$307,"M",'Classification Matrix'!$H$2:$H$307,F$4)+COUNTIFS('Classification Matrix'!$D$2:$D$307,"M",'Classification Matrix'!$I$2:$I$307,F$4) | G17: =COUNTIFS('Classification Matrix'!$D$2:$D$307,"M",'Classification Matrix'!$G$2:$G$307,G$4)+COUNTIFS('Classification Matrix'!$D$2:$D$307,"M",'Classification Matrix'!$H$2:$H$307,G$4)+COUNTIFS('Classification Matrix'!$D$2:$D$307,"M",'Classification Matrix'!$I$2:$I$307,G$4) | H17: =COUNTIFS('Classification Matrix'!$D$2:$D$307,"M",'Classification Matrix'!$G$2:$G$307,H$4)+COUNTIFS('Classification Matrix'!$D$2:$D$307,"M",'Classification Matrix'!$H$2:$H$307,H$4)+COUNTIFS('Classification Matrix'!$D$2:$D$307,"M",'Classification Matrix'!$I$2:$I$307,H$4) | I17: =COUNTIFS('Classification Matrix'!$D$2:$D$307,"M",'Classification Matrix'!$G$2:$G$307,I$4)+COUNTIFS('Classification Matrix'!$D$2:$D$307,"M",'Classification Matrix'!$H$2:$H$307,I$4)+COUNTIFS('Classification Matrix'!$D$2:$D$307,"M",'Classification Matrix'!$I$2:$I$307,I$4) | J17: =COUNTIFS('Classification Matrix'!$D$2:$D$307,"M",'Classification Matrix'!$G$2:$G$307,J$4)+COUNTIFS('Classification Matrix'!$D$2:$D$307,"M",'Classification Matrix'!$H$2:$H$307,J$4)+COUNTIFS('Classification Matrix'!$D$2:$D$307,"M",'Classification Matrix'!$I$2:$I$307,J$4) | ... L17: =COUNTIFS('Classification Matrix'!$D$2:$D$307,"M",'Classification Matrix'!$G$2:$G$307,L$4)+COUNTIFS('Classification Matrix'!$D$2:$D$307,"M",'Classification Matrix'!$H$2:$H$307,L$4)+COUNTIFS('Classification Matrix'!$D$2:$D$307,"M",'Classification Matrix'!$I$2:$I$307,L$4) | M17: =COUNTIF(C17:L17,">0")
A18: N. Monomials | B18: =COUNTIF('Classification Matrix'!$D$2:$D$307,"N") | C18: =COUNTIFS('Classification Matrix'!$D$2:$D$307,"N",'Classification Matrix'!$G$2:$G$307,C$4)+COUNTIFS('Classification Matrix'!$D$2:$D$307,"N",'Classification Matrix'!$H$2:$H$307,C$4)+COUNTIFS('Classification Matrix'!$D$2:$D$307,"N",'Classification Matrix'!$I$2:$I$307,C$4) | D18: =COUNTIFS('Classification Matrix'!$D$2:$D$307,"N",'Classification Matrix'!$G$2:$G$307,D$4)+COUNTIFS('Classification Matrix'!$D$2:$D$307,"N",'Classification Matrix'!$H$2:$H$307,D$4)+COUNTIFS('Classification Matrix'!$D$2:$D$307,"N",'Classification Matrix'!$I$2:$I$307,D$4) | E18: =COUNTIFS('Classification Matrix'!$D$2:$D$307,"N",'Classification Matrix'!$G$2:$G$307,E$4)+COUNTIFS('Classification Matrix'!$D$2:$D$307,"N",'Classification Matrix'!$H$2:$H$307,E$4)+COUNTIFS('Classification Matrix'!$D$2:$D$307,"N",'Classification Matrix'!$I$2:$I$307,E$4) | F18: =COUNTIFS('Classification Matrix'!$D$2:$D$307,"N",'Classification Matrix'!$G$2:$G$307,F$4)+COUNTIFS('Classification Matrix'!$D$2:$D$307,"N",'Classification Matrix'!$H$2:$H$307,F$4)+COUNTIFS('Classification Matrix'!$D$2:$D$307,"N",'Classification Matrix'!$I$2:$I$307,F$4) | G18: =COUNTIFS('Classification Matrix'!$D$2:$D$307,"N",'Classification Matrix'!$G$2:$G$307,G$4)+COUNTIFS('Classification Matrix'!$D$2:$D$307,"N",'Classification Matrix'!$H$2:$H$307,G$4)+COUNTIFS('Classification Matrix'!$D$2:$D$307,"N",'Classification Matrix'!$I$2:$I$307,G$4) | H18: =COUNTIFS('Classification Matrix'!$D$2:$D$307,"N",'Classification Matrix'!$G$2:$G$307,H$4)+COUNTIFS('Classification Matrix'!$D$2:$D$307,"N",'Classification Matrix'!$H$2:$H$307,H$4)+COUNTIFS('Classification Matrix'!$D$2:$D$307,"N",'Classification Matrix'!$I$2:$I$307,H$4) | I18: =COUNTIFS('Classification Matrix'!$D$2:$D$307,"N",'Classification Matrix'!$G$2:$G$307,I$4)+COUNTIFS('Classification Matrix'!$D$2:$D$307,"N",'Classification Matrix'!$H$2:$H$307,I$4)+COUNTIFS('Classification Matrix'!$D$2:$D$307,"N",'Classification Matrix'!$I$2:$I$307,I$4) | J18: =COUNTIFS('Classification Matrix'!$D$2:$D$307,"N",'Classification Matrix'!$G$2:$G$307,J$4)+COUNTIFS('Classification Matrix'!$D$2:$D$307,"N",'Classification Matrix'!$H$2:$H$307,J$4)+COUNTIFS('Classification Matrix'!$D$2:$D$307,"N",'Classification Matrix'!$I$2:$I$307,J$4) | ... L18: =COUNTIFS('Classification Matrix'!$D$2:$D$307,"N",'Classification Matrix'!$G$2:$G$307,L$4)+COUNTIFS('Classification Matrix'!$D$2:$D$307,"N",'Classification Matrix'!$H$2:$H$307,L$4)+COUNTIFS('Classification Matrix'!$D$2:$D$307,"N",'Classification Matrix'!$I$2:$I$307,L$4) | M18: =COUNTIF(C18:L18,">0")
A19: O. Polynomials | B19: =COUNTIF('Classification Matrix'!$D$2:$D$307,"O") | C19: =COUNTIFS('Classification Matrix'!$D$2:$D$307,"O",'Classification Matrix'!$G$2:$G$307,C$4)+COUNTIFS('Classification Matrix'!$D$2:$D$307,"O",'Classification Matrix'!$H$2:$H$307,C$4)+COUNTIFS('Classification Matrix'!$D$2:$D$307,"O",'Classification Matrix'!$I$2:$I$307,C$4) | D19: =COUNTIFS('Classification Matrix'!$D$2:$D$307,"O",'Classification Matrix'!$G$2:$G$307,D$4)+COUNTIFS('Classification Matrix'!$D$2:$D$307,"O",'Classification Matrix'!$H$2:$H$307,D$4)+COUNTIFS('Classification Matrix'!$D$2:$D$307,"O",'Classification Matrix'!$I$2:$I$307,D$4) | E19: =COUNTIFS('Classification Matrix'!$D$2:$D$307,"O",'Classification Matrix'!$G$2:$G$307,E$4)+COUNTIFS('Classification Matrix'!$D$2:$D$307,"O",'Classification Matrix'!$H$2:$H$307,E$4)+COUNTIFS('Classification Matrix'!$D$2:$D$307,"O",'Classification Matrix'!$I$2:$I$307,E$4) | F19: =COUNTIFS('Classification Matrix'!$D$2:$D$307,"O",'Classification Matrix'!$G$2:$G$307,F$4)+COUNTIFS('Classification Matrix'!$D$2:$D$307,"O",'Classification Matrix'!$H$2:$H$307,F$4)+COUNTIFS('Classification Matrix'!$D$2:$D$307,"O",'Classification Matrix'!$I$2:$I$307,F$4) | G19: =COUNTIFS('Classification Matrix'!$D$2:$D$307,"O",'Classification Matrix'!$G$2:$G$307,G$4)+COUNTIFS('Classification Matrix'!$D$2:$D$307,"O",'Classification Matrix'!$H$2:$H$307,G$4)+COUNTIFS('Classification Matrix'!$D$2:$D$307,"O",'Classification Matrix'!$I$2:$I$307,G$4) | H19: =COUNTIFS('Classification Matrix'!$D$2:$D$307,"O",'Classification Matrix'!$G$2:$G$307,H$4)+COUNTIFS('Classification Matrix'!$D$2:$D$307,"O",'Classification Matrix'!$H$2:$H$307,H$4)+COUNTIFS('Classification Matrix'!$D$2:$D$307,"O",'Classification Matrix'!$I$2:$I$307,H$4) | I19: =COUNTIFS('Classification Matrix'!$D$2:$D$307,"O",'Classification Matrix'!$G$2:$G$307,I$4)+COUNTIFS('Classification Matrix'!$D$2:$D$307,"O",'Classification Matrix'!$H$2:$H$307,I$4)+COUNTIFS('Classification Matrix'!$D$2:$D$307,"O",'Classification Matrix'!$I$2:$I$307,I$4) | J19: =COUNTIFS('Classification Matrix'!$D$2:$D$307,"O",'Classification Matrix'!$G$2:$G$307,J$4)+COUNTIFS('Classification Matrix'!$D$2:$D$307,"O",'Classification Matrix'!$H$2:$H$307,J$4)+COUNTIFS('Classification Matrix'!$D$2:$D$307,"O",'Classification Matrix'!$I$2:$I$307,J$4) | ... L19: =COUNTIFS('Classification Matrix'!$D$2:$D$307,"O",'Classification Matrix'!$G$2:$G$307,L$4)+COUNTIFS('Classification Matrix'!$D$2:$D$307,"O",'Classification Matrix'!$H$2:$H$307,L$4)+COUNTIFS('Classification Matrix'!$D$2:$D$307,"O",'Classification Matrix'!$I$2:$I$307,L$4) | M19: =COUNTIF(C19:L19,">0")
